~/workspace$ pytest tests/test_20_database_connection_coverage.py
================================== test session starts ==================================
platform linux -- Python 3.11.13, pytest-8.4.2, pluggy-1.6.0
rootdir: /home/runner/workspace
configfile: pyproject.toml
plugins: cov-6.2.1, mock-3.15.0
collected 25 items                                                                      

tests/test_20_database_connection_coverage.py F.FFFF..FFFF...F..FF.FFFF           [100%]

======================================= FAILURES ========================================
___________________ TestDatabaseConnection.test_init_with_env_params ____________________

self = <tests.test_20_database_connection_coverage.TestDatabaseConnection object at 0x7f7c04b0a210>

    @patch.dict('os.environ', {
        'PGHOST': 'test-host',
        'PGPORT': '5433',
        'PGDATABASE': 'test-db',
        'PGUSER': 'test-user',
        'PGPASSWORD': 'test-pass'
    })
    def test_init_with_env_params(self):
        """Покрытие инициализации с параметрами из env"""
        db_conn = DatabaseConnection()
    
>       assert db_conn._connection_params == {
            "host": "test-host",
            "port": "5433",
            "database": "test-db",
            "user": "test-user",
            "password": "test-pass"
        }
E       AssertionError: assert {'command_tim...on.tech', ...} == {'database': ...: '5433', ...}
E         
E         Omitting 1 identical items, use -vv to show
E         Differing items:
E         {'password': 'npg_MPnXu1JWZ5jB'} != {'password': 'test-pass'}
E         {'database': 'neondb'} != {'database': '...
E         
E         ...Full output truncated (6 lines hidden), use '-vv' to show

tests/test_20_database_connection_coverage.py:59: AssertionError
________________ TestDatabaseConnection.test_get_default_params_defaults ________________

self = <tests.test_20_database_connection_coverage.TestDatabaseConnection object at 0x7f7c04b3a250>

    @patch.dict('os.environ', {}, clear=True)
    def test_get_default_params_defaults(self):
        """Покрытие параметров по умолчанию"""
        db_conn = DatabaseConnection()
    
        expected_params = {
            "host": "localhost",
            "port": "5432",
            "database": "postgres",
            "user": "postgres",
            "password": ""
        }
    
>       assert db_conn._connection_params == expected_params
E       AssertionError: assert {'command_tim...calhost', ...} == {'database': ...: '5432', ...}
E         
E         Omitting 5 identical items, use -vv to show
E         Left contains 2 more items:
E         {'command_timeout': '30', 'connect_timeout': '10'}
E         Use -v to get more diff

tests/test_20_database_connection_coverage.py:96: AssertionError
___________ TestDatabaseConnection.test_get_connection_creates_new_when_none ____________

args = (<tests.test_20_database_connection_coverage.TestDatabaseConnection object at 0x7f7c04b3a850>,)
keywargs = {}

    @wraps(func)
    def patched(*args, **keywargs):
>       with self.decoration_helper(patched,
                                    args,
                                    keywargs) as (newargs, newkeywargs):

/nix/store/7d088dip86hlzri9sk0h78b63yfmx0a0-python3-3.11.13/lib/python3.11/unittest/mock.py:1375: 
_ _ _ _ _ _ _ _ _ _ _ _ _ _ _ _ _ _ _ _ _ _ _ _ _ _ _ _ _ _ _ _ _ _ _ _ _ _ _ _ _ _ _ _ _
/nix/store/7d088dip86hlzri9sk0h78b63yfmx0a0-python3-3.11.13/lib/python3.11/contextlib.py:137: in __enter__
    return next(self.gen)
           ^^^^^^^^^^^^^^
/nix/store/7d088dip86hlzri9sk0h78b63yfmx0a0-python3-3.11.13/lib/python3.11/unittest/mock.py:1357: in decoration_helper
    arg = exit_stack.enter_context(patching)
          ^^^^^^^^^^^^^^^^^^^^^^^^^^^^^^^^^^
/nix/store/7d088dip86hlzri9sk0h78b63yfmx0a0-python3-3.11.13/lib/python3.11/contextlib.py:517: in enter_context
    result = _enter(cm)
             ^^^^^^^^^^
/nix/store/7d088dip86hlzri9sk0h78b63yfmx0a0-python3-3.11.13/lib/python3.11/unittest/mock.py:1446: in __enter__
    original, local = self.get_original()
                      ^^^^^^^^^^^^^^^^^^^
_ _ _ _ _ _ _ _ _ _ _ _ _ _ _ _ _ _ _ _ _ _ _ _ _ _ _ _ _ _ _ _ _ _ _ _ _ _ _ _ _ _ _ _ _

self = <unittest.mock._patch object at 0x7f7c04b2a690>

    def get_original(self):
        target = self.getter()
        name = self.attribute
    
        original = DEFAULT
        local = False
    
        try:
            original = target.__dict__[name]
        except (AttributeError, KeyError):
            original = getattr(target, name, DEFAULT)
        else:
            local = True
    
        if name in _builtins and isinstance(target, ModuleType):
            self.create = True
    
        if not self.create and original is DEFAULT:
>           raise AttributeError(
                "%s does not have the attribute %r" % (target, name)
            )
E           AttributeError: <module 'src.storage.components.database_connection' from '/home/runner/workspace/src/storage/components/database_connection.py'> does not have the attribute 'psycopg2'

/nix/store/7d088dip86hlzri9sk0h78b63yfmx0a0-python3-3.11.13/lib/python3.11/unittest/mock.py:1419: AttributeError
__________ TestDatabaseConnection.test_get_connection_reuses_valid_connection ___________

args = (<tests.test_20_database_connection_coverage.TestDatabaseConnection object at 0x7f7c04b3ae10>,)
keywargs = {}

    @wraps(func)
    def patched(*args, **keywargs):
>       with self.decoration_helper(patched,
                                    args,
                                    keywargs) as (newargs, newkeywargs):

/nix/store/7d088dip86hlzri9sk0h78b63yfmx0a0-python3-3.11.13/lib/python3.11/unittest/mock.py:1375: 
_ _ _ _ _ _ _ _ _ _ _ _ _ _ _ _ _ _ _ _ _ _ _ _ _ _ _ _ _ _ _ _ _ _ _ _ _ _ _ _ _ _ _ _ _
/nix/store/7d088dip86hlzri9sk0h78b63yfmx0a0-python3-3.11.13/lib/python3.11/contextlib.py:137: in __enter__
    return next(self.gen)
           ^^^^^^^^^^^^^^
/nix/store/7d088dip86hlzri9sk0h78b63yfmx0a0-python3-3.11.13/lib/python3.11/unittest/mock.py:1357: in decoration_helper
    arg = exit_stack.enter_context(patching)
          ^^^^^^^^^^^^^^^^^^^^^^^^^^^^^^^^^^
/nix/store/7d088dip86hlzri9sk0h78b63yfmx0a0-python3-3.11.13/lib/python3.11/contextlib.py:517: in enter_context
    result = _enter(cm)
             ^^^^^^^^^^
/nix/store/7d088dip86hlzri9sk0h78b63yfmx0a0-python3-3.11.13/lib/python3.11/unittest/mock.py:1446: in __enter__
    original, local = self.get_original()
                      ^^^^^^^^^^^^^^^^^^^
_ _ _ _ _ _ _ _ _ _ _ _ _ _ _ _ _ _ _ _ _ _ _ _ _ _ _ _ _ _ _ _ _ _ _ _ _ _ _ _ _ _ _ _ _

self = <unittest.mock._patch object at 0x7f7c04b2a850>

    def get_original(self):
        target = self.getter()
        name = self.attribute
    
        original = DEFAULT
        local = False
    
        try:
            original = target.__dict__[name]
        except (AttributeError, KeyError):
            original = getattr(target, name, DEFAULT)
        else:
            local = True
    
        if name in _builtins and isinstance(target, ModuleType):
            self.create = True
    
        if not self.create and original is DEFAULT:
>           raise AttributeError(
                "%s does not have the attribute %r" % (target, name)
            )
E           AttributeError: <module 'src.storage.components.database_connection' from '/home/runner/workspace/src/storage/components/database_connection.py'> does not have the attribute 'psycopg2'

/nix/store/7d088dip86hlzri9sk0h78b63yfmx0a0-python3-3.11.13/lib/python3.11/unittest/mock.py:1419: AttributeError
________ TestDatabaseConnection.test_get_connection_recreates_invalid_connection ________

args = (<tests.test_20_database_connection_coverage.TestDatabaseConnection object at 0x7f7c04b3b3d0>,)
keywargs = {}

    @wraps(func)
    def patched(*args, **keywargs):
>       with self.decoration_helper(patched,
                                    args,
                                    keywargs) as (newargs, newkeywargs):

/nix/store/7d088dip86hlzri9sk0h78b63yfmx0a0-python3-3.11.13/lib/python3.11/unittest/mock.py:1375: 
_ _ _ _ _ _ _ _ _ _ _ _ _ _ _ _ _ _ _ _ _ _ _ _ _ _ _ _ _ _ _ _ _ _ _ _ _ _ _ _ _ _ _ _ _
/nix/store/7d088dip86hlzri9sk0h78b63yfmx0a0-python3-3.11.13/lib/python3.11/contextlib.py:137: in __enter__
    return next(self.gen)
           ^^^^^^^^^^^^^^
/nix/store/7d088dip86hlzri9sk0h78b63yfmx0a0-python3-3.11.13/lib/python3.11/unittest/mock.py:1357: in decoration_helper
    arg = exit_stack.enter_context(patching)
          ^^^^^^^^^^^^^^^^^^^^^^^^^^^^^^^^^^
/nix/store/7d088dip86hlzri9sk0h78b63yfmx0a0-python3-3.11.13/lib/python3.11/contextlib.py:517: in enter_context
    result = _enter(cm)
             ^^^^^^^^^^
/nix/store/7d088dip86hlzri9sk0h78b63yfmx0a0-python3-3.11.13/lib/python3.11/unittest/mock.py:1446: in __enter__
    original, local = self.get_original()
                      ^^^^^^^^^^^^^^^^^^^
_ _ _ _ _ _ _ _ _ _ _ _ _ _ _ _ _ _ _ _ _ _ _ _ _ _ _ _ _ _ _ _ _ _ _ _ _ _ _ _ _ _ _ _ _

self = <unittest.mock._patch object at 0x7f7c04b2aa10>

    def get_original(self):
        target = self.getter()
        name = self.attribute
    
        original = DEFAULT
        local = False
    
        try:
            original = target.__dict__[name]
        except (AttributeError, KeyError):
            original = getattr(target, name, DEFAULT)
        else:
            local = True
    
        if name in _builtins and isinstance(target, ModuleType):
            self.create = True
    
        if not self.create and original is DEFAULT:
>           raise AttributeError(
                "%s does not have the attribute %r" % (target, name)
            )
E           AttributeError: <module 'src.storage.components.database_connection' from '/home/runner/workspace/src/storage/components/database_connection.py'> does not have the attribute 'psycopg2'

/nix/store/7d088dip86hlzri9sk0h78b63yfmx0a0-python3-3.11.13/lib/python3.11/unittest/mock.py:1419: AttributeError
___________ TestDatabaseConnection.test_is_connection_valid_broken_connection ___________

args = (<tests.test_20_database_connection_coverage.TestDatabaseConnection object at 0x7f7c04b3c6d0>,)
keywargs = {}

    @wraps(func)
    def patched(*args, **keywargs):
>       with self.decoration_helper(patched,
                                    args,
                                    keywargs) as (newargs, newkeywargs):

/nix/store/7d088dip86hlzri9sk0h78b63yfmx0a0-python3-3.11.13/lib/python3.11/unittest/mock.py:1375: 
_ _ _ _ _ _ _ _ _ _ _ _ _ _ _ _ _ _ _ _ _ _ _ _ _ _ _ _ _ _ _ _ _ _ _ _ _ _ _ _ _ _ _ _ _
/nix/store/7d088dip86hlzri9sk0h78b63yfmx0a0-python3-3.11.13/lib/python3.11/contextlib.py:137: in __enter__
    return next(self.gen)
           ^^^^^^^^^^^^^^
/nix/store/7d088dip86hlzri9sk0h78b63yfmx0a0-python3-3.11.13/lib/python3.11/unittest/mock.py:1357: in decoration_helper
    arg = exit_stack.enter_context(patching)
          ^^^^^^^^^^^^^^^^^^^^^^^^^^^^^^^^^^
/nix/store/7d088dip86hlzri9sk0h78b63yfmx0a0-python3-3.11.13/lib/python3.11/contextlib.py:517: in enter_context
    result = _enter(cm)
             ^^^^^^^^^^
/nix/store/7d088dip86hlzri9sk0h78b63yfmx0a0-python3-3.11.13/lib/python3.11/unittest/mock.py:1446: in __enter__
    original, local = self.get_original()
                      ^^^^^^^^^^^^^^^^^^^
_ _ _ _ _ _ _ _ _ _ _ _ _ _ _ _ _ _ _ _ _ _ _ _ _ _ _ _ _ _ _ _ _ _ _ _ _ _ _ _ _ _ _ _ _

self = <unittest.mock._patch object at 0x7f7c04b2abd0>

    def get_original(self):
        target = self.getter()
        name = self.attribute
    
        original = DEFAULT
        local = False
    
        try:
            original = target.__dict__[name]
        except (AttributeError, KeyError):
            original = getattr(target, name, DEFAULT)
        else:
            local = True
    
        if name in _builtins and isinstance(target, ModuleType):
            self.create = True
    
        if not self.create and original is DEFAULT:
>           raise AttributeError(
                "%s does not have the attribute %r" % (target, name)
            )
E           AttributeError: <module 'src.storage.components.database_connection' from '/home/runner/workspace/src/storage/components/database_connection.py'> does not have the attribute 'psycopg2'

/nix/store/7d088dip86hlzri9sk0h78b63yfmx0a0-python3-3.11.13/lib/python3.11/unittest/mock.py:1419: AttributeError
_______________ TestDatabaseConnection.test_create_new_connection_success _______________

args = (<tests.test_20_database_connection_coverage.TestDatabaseConnection object at 0x7f7c04b3cd10>,)
keywargs = {}

    @wraps(func)
    def patched(*args, **keywargs):
>       with self.decoration_helper(patched,
                                    args,
                                    keywargs) as (newargs, newkeywargs):

/nix/store/7d088dip86hlzri9sk0h78b63yfmx0a0-python3-3.11.13/lib/python3.11/unittest/mock.py:1375: 
_ _ _ _ _ _ _ _ _ _ _ _ _ _ _ _ _ _ _ _ _ _ _ _ _ _ _ _ _ _ _ _ _ _ _ _ _ _ _ _ _ _ _ _ _
/nix/store/7d088dip86hlzri9sk0h78b63yfmx0a0-python3-3.11.13/lib/python3.11/contextlib.py:137: in __enter__
    return next(self.gen)
           ^^^^^^^^^^^^^^
/nix/store/7d088dip86hlzri9sk0h78b63yfmx0a0-python3-3.11.13/lib/python3.11/unittest/mock.py:1357: in decoration_helper
    arg = exit_stack.enter_context(patching)
          ^^^^^^^^^^^^^^^^^^^^^^^^^^^^^^^^^^
/nix/store/7d088dip86hlzri9sk0h78b63yfmx0a0-python3-3.11.13/lib/python3.11/contextlib.py:517: in enter_context
    result = _enter(cm)
             ^^^^^^^^^^
/nix/store/7d088dip86hlzri9sk0h78b63yfmx0a0-python3-3.11.13/lib/python3.11/unittest/mock.py:1446: in __enter__
    original, local = self.get_original()
                      ^^^^^^^^^^^^^^^^^^^
_ _ _ _ _ _ _ _ _ _ _ _ _ _ _ _ _ _ _ _ _ _ _ _ _ _ _ _ _ _ _ _ _ _ _ _ _ _ _ _ _ _ _ _ _

self = <unittest.mock._patch object at 0x7f7c04b2ad90>

    def get_original(self):
        target = self.getter()
        name = self.attribute
    
        original = DEFAULT
        local = False
    
        try:
            original = target.__dict__[name]
        except (AttributeError, KeyError):
            original = getattr(target, name, DEFAULT)
        else:
            local = True
    
        if name in _builtins and isinstance(target, ModuleType):
            self.create = True
    
        if not self.create and original is DEFAULT:
>           raise AttributeError(
                "%s does not have the attribute %r" % (target, name)
            )
E           AttributeError: <module 'src.storage.components.database_connection' from '/home/runner/workspace/src/storage/components/database_connection.py'> does not have the attribute 'psycopg2'

/nix/store/7d088dip86hlzri9sk0h78b63yfmx0a0-python3-3.11.13/lib/python3.11/unittest/mock.py:1419: AttributeError
_______________ TestDatabaseConnection.test_create_new_connection_failure _______________

args = (<tests.test_20_database_connection_coverage.TestDatabaseConnection object at 0x7f7c04b3d390>,)
keywargs = {}

    @wraps(func)
    def patched(*args, **keywargs):
>       with self.decoration_helper(patched,
                                    args,
                                    keywargs) as (newargs, newkeywargs):

/nix/store/7d088dip86hlzri9sk0h78b63yfmx0a0-python3-3.11.13/lib/python3.11/unittest/mock.py:1375: 
_ _ _ _ _ _ _ _ _ _ _ _ _ _ _ _ _ _ _ _ _ _ _ _ _ _ _ _ _ _ _ _ _ _ _ _ _ _ _ _ _ _ _ _ _
/nix/store/7d088dip86hlzri9sk0h78b63yfmx0a0-python3-3.11.13/lib/python3.11/contextlib.py:137: in __enter__
    return next(self.gen)
           ^^^^^^^^^^^^^^
/nix/store/7d088dip86hlzri9sk0h78b63yfmx0a0-python3-3.11.13/lib/python3.11/unittest/mock.py:1357: in decoration_helper
    arg = exit_stack.enter_context(patching)
          ^^^^^^^^^^^^^^^^^^^^^^^^^^^^^^^^^^
/nix/store/7d088dip86hlzri9sk0h78b63yfmx0a0-python3-3.11.13/lib/python3.11/contextlib.py:517: in enter_context
    result = _enter(cm)
             ^^^^^^^^^^
/nix/store/7d088dip86hlzri9sk0h78b63yfmx0a0-python3-3.11.13/lib/python3.11/unittest/mock.py:1446: in __enter__
    original, local = self.get_original()
                      ^^^^^^^^^^^^^^^^^^^
_ _ _ _ _ _ _ _ _ _ _ _ _ _ _ _ _ _ _ _ _ _ _ _ _ _ _ _ _ _ _ _ _ _ _ _ _ _ _ _ _ _ _ _ _

self = <unittest.mock._patch object at 0x7f7c04b2b190>

    def get_original(self):
        target = self.getter()
        name = self.attribute
    
        original = DEFAULT
        local = False
    
        try:
            original = target.__dict__[name]
        except (AttributeError, KeyError):
            original = getattr(target, name, DEFAULT)
        else:
            local = True
    
        if name in _builtins and isinstance(target, ModuleType):
            self.create = True
    
        if not self.create and original is DEFAULT:
>           raise AttributeError(
                "%s does not have the attribute %r" % (target, name)
            )
E           AttributeError: <module 'src.storage.components.database_connection' from '/home/runner/workspace/src/storage/components/database_connection.py'> does not have the attribute 'psycopg2'

/nix/store/7d088dip86hlzri9sk0h78b63yfmx0a0-python3-3.11.13/lib/python3.11/unittest/mock.py:1419: AttributeError
_________ TestDatabaseConnection.test_create_new_connection_with_cursor_factory _________

args = (<tests.test_20_database_connection_coverage.TestDatabaseConnection object at 0x7f7c04b3da10>,)
keywargs = {}

    @wraps(func)
    def patched(*args, **keywargs):
>       with self.decoration_helper(patched,
                                    args,
                                    keywargs) as (newargs, newkeywargs):

/nix/store/7d088dip86hlzri9sk0h78b63yfmx0a0-python3-3.11.13/lib/python3.11/unittest/mock.py:1375: 
_ _ _ _ _ _ _ _ _ _ _ _ _ _ _ _ _ _ _ _ _ _ _ _ _ _ _ _ _ _ _ _ _ _ _ _ _ _ _ _ _ _ _ _ _
/nix/store/7d088dip86hlzri9sk0h78b63yfmx0a0-python3-3.11.13/lib/python3.11/contextlib.py:137: in __enter__
    return next(self.gen)
           ^^^^^^^^^^^^^^
/nix/store/7d088dip86hlzri9sk0h78b63yfmx0a0-python3-3.11.13/lib/python3.11/unittest/mock.py:1357: in decoration_helper
    arg = exit_stack.enter_context(patching)
          ^^^^^^^^^^^^^^^^^^^^^^^^^^^^^^^^^^
/nix/store/7d088dip86hlzri9sk0h78b63yfmx0a0-python3-3.11.13/lib/python3.11/contextlib.py:517: in enter_context
    result = _enter(cm)
             ^^^^^^^^^^
/nix/store/7d088dip86hlzri9sk0h78b63yfmx0a0-python3-3.11.13/lib/python3.11/unittest/mock.py:1446: in __enter__
    original, local = self.get_original()
                      ^^^^^^^^^^^^^^^^^^^
_ _ _ _ _ _ _ _ _ _ _ _ _ _ _ _ _ _ _ _ _ _ _ _ _ _ _ _ _ _ _ _ _ _ _ _ _ _ _ _ _ _ _ _ _

self = <unittest.mock._patch object at 0x7f7c04b2b590>

    def get_original(self):
        target = self.getter()
        name = self.attribute
    
        original = DEFAULT
        local = False
    
        try:
            original = target.__dict__[name]
        except (AttributeError, KeyError):
            original = getattr(target, name, DEFAULT)
        else:
            local = True
    
        if name in _builtins and isinstance(target, ModuleType):
            self.create = True
    
        if not self.create and original is DEFAULT:
>           raise AttributeError(
                "%s does not have the attribute %r" % (target, name)
            )
E           AttributeError: <module 'src.storage.components.database_connection' from '/home/runner/workspace/src/storage/components/database_connection.py'> does not have the attribute 'RealDictCursor'

/nix/store/7d088dip86hlzri9sk0h78b63yfmx0a0-python3-3.11.13/lib/python3.11/unittest/mock.py:1419: AttributeError
_________________ TestDatabaseConnection.test_context_manager_protocol __________________

args = (<tests.test_20_database_connection_coverage.TestDatabaseConnection object at 0x7f7c04b3f4d0>,)
keywargs = {}

    @wraps(func)
    def patched(*args, **keywargs):
>       with self.decoration_helper(patched,
                                    args,
                                    keywargs) as (newargs, newkeywargs):

/nix/store/7d088dip86hlzri9sk0h78b63yfmx0a0-python3-3.11.13/lib/python3.11/unittest/mock.py:1375: 
_ _ _ _ _ _ _ _ _ _ _ _ _ _ _ _ _ _ _ _ _ _ _ _ _ _ _ _ _ _ _ _ _ _ _ _ _ _ _ _ _ _ _ _ _
/nix/store/7d088dip86hlzri9sk0h78b63yfmx0a0-python3-3.11.13/lib/python3.11/contextlib.py:137: in __enter__
    return next(self.gen)
           ^^^^^^^^^^^^^^
/nix/store/7d088dip86hlzri9sk0h78b63yfmx0a0-python3-3.11.13/lib/python3.11/unittest/mock.py:1357: in decoration_helper
    arg = exit_stack.enter_context(patching)
          ^^^^^^^^^^^^^^^^^^^^^^^^^^^^^^^^^^
/nix/store/7d088dip86hlzri9sk0h78b63yfmx0a0-python3-3.11.13/lib/python3.11/contextlib.py:517: in enter_context
    result = _enter(cm)
             ^^^^^^^^^^
/nix/store/7d088dip86hlzri9sk0h78b63yfmx0a0-python3-3.11.13/lib/python3.11/unittest/mock.py:1446: in __enter__
    original, local = self.get_original()
                      ^^^^^^^^^^^^^^^^^^^
_ _ _ _ _ _ _ _ _ _ _ _ _ _ _ _ _ _ _ _ _ _ _ _ _ _ _ _ _ _ _ _ _ _ _ _ _ _ _ _ _ _ _ _ _

self = <unittest.mock._patch object at 0x7f7c04b2b950>

    def get_original(self):
        target = self.getter()
        name = self.attribute
    
        original = DEFAULT
        local = False
    
        try:
            original = target.__dict__[name]
        except (AttributeError, KeyError):
            original = getattr(target, name, DEFAULT)
        else:
            local = True
    
        if name in _builtins and isinstance(target, ModuleType):
            self.create = True
    
        if not self.create and original is DEFAULT:
>           raise AttributeError(
                "%s does not have the attribute %r" % (target, name)
            )
E           AttributeError: <module 'src.storage.components.database_connection' from '/home/runner/workspace/src/storage/components/database_connection.py'> does not have the attribute 'psycopg2'

/nix/store/7d088dip86hlzri9sk0h78b63yfmx0a0-python3-3.11.13/lib/python3.11/unittest/mock.py:1419: AttributeError
______________ TestDatabaseConnectionEdgeCases.test_psycopg2_not_available ______________

args = (<tests.test_20_database_connection_coverage.TestDatabaseConnectionEdgeCases object at 0x7f7c04b3f790>,)
keywargs = {}

    @wraps(func)
    def patched(*args, **keywargs):
>       with self.decoration_helper(patched,
                                    args,
                                    keywargs) as (newargs, newkeywargs):

/nix/store/7d088dip86hlzri9sk0h78b63yfmx0a0-python3-3.11.13/lib/python3.11/unittest/mock.py:1375: 
_ _ _ _ _ _ _ _ _ _ _ _ _ _ _ _ _ _ _ _ _ _ _ _ _ _ _ _ _ _ _ _ _ _ _ _ _ _ _ _ _ _ _ _ _
/nix/store/7d088dip86hlzri9sk0h78b63yfmx0a0-python3-3.11.13/lib/python3.11/contextlib.py:137: in __enter__
    return next(self.gen)
           ^^^^^^^^^^^^^^
/nix/store/7d088dip86hlzri9sk0h78b63yfmx0a0-python3-3.11.13/lib/python3.11/unittest/mock.py:1357: in decoration_helper
    arg = exit_stack.enter_context(patching)
          ^^^^^^^^^^^^^^^^^^^^^^^^^^^^^^^^^^
/nix/store/7d088dip86hlzri9sk0h78b63yfmx0a0-python3-3.11.13/lib/python3.11/contextlib.py:517: in enter_context
    result = _enter(cm)
             ^^^^^^^^^^
/nix/store/7d088dip86hlzri9sk0h78b63yfmx0a0-python3-3.11.13/lib/python3.11/unittest/mock.py:1446: in __enter__
    original, local = self.get_original()
                      ^^^^^^^^^^^^^^^^^^^
_ _ _ _ _ _ _ _ _ _ _ _ _ _ _ _ _ _ _ _ _ _ _ _ _ _ _ _ _ _ _ _ _ _ _ _ _ _ _ _ _ _ _ _ _

self = <unittest.mock._patch object at 0x7f7c04b2bed0>

    def get_original(self):
        target = self.getter()
        name = self.attribute
    
        original = DEFAULT
        local = False
    
        try:
            original = target.__dict__[name]
        except (AttributeError, KeyError):
            original = getattr(target, name, DEFAULT)
        else:
            local = True
    
        if name in _builtins and isinstance(target, ModuleType):
            self.create = True
    
        if not self.create and original is DEFAULT:
>           raise AttributeError(
                "%s does not have the attribute %r" % (target, name)
            )
E           AttributeError: <module 'src.storage.components.database_connection' from '/home/runner/workspace/src/storage/components/database_connection.py'> does not have the attribute 'psycopg2'

/nix/store/7d088dip86hlzri9sk0h78b63yfmx0a0-python3-3.11.13/lib/python3.11/unittest/mock.py:1419: AttributeError
__________ TestDatabaseConnectionEdgeCases.test_real_dict_cursor_not_available __________

args = (<tests.test_20_database_connection_coverage.TestDatabaseConnectionEdgeCases object at 0x7f7c04b3fb10>,)
keywargs = {}

    @wraps(func)
    def patched(*args, **keywargs):
>       with self.decoration_helper(patched,
                                    args,
                                    keywargs) as (newargs, newkeywargs):

/nix/store/7d088dip86hlzri9sk0h78b63yfmx0a0-python3-3.11.13/lib/python3.11/unittest/mock.py:1375: 
_ _ _ _ _ _ _ _ _ _ _ _ _ _ _ _ _ _ _ _ _ _ _ _ _ _ _ _ _ _ _ _ _ _ _ _ _ _ _ _ _ _ _ _ _
/nix/store/7d088dip86hlzri9sk0h78b63yfmx0a0-python3-3.11.13/lib/python3.11/contextlib.py:137: in __enter__
    return next(self.gen)
           ^^^^^^^^^^^^^^
/nix/store/7d088dip86hlzri9sk0h78b63yfmx0a0-python3-3.11.13/lib/python3.11/unittest/mock.py:1357: in decoration_helper
    arg = exit_stack.enter_context(patching)
          ^^^^^^^^^^^^^^^^^^^^^^^^^^^^^^^^^^
/nix/store/7d088dip86hlzri9sk0h78b63yfmx0a0-python3-3.11.13/lib/python3.11/contextlib.py:517: in enter_context
    result = _enter(cm)
             ^^^^^^^^^^
/nix/store/7d088dip86hlzri9sk0h78b63yfmx0a0-python3-3.11.13/lib/python3.11/unittest/mock.py:1446: in __enter__
    original, local = self.get_original()
                      ^^^^^^^^^^^^^^^^^^^
_ _ _ _ _ _ _ _ _ _ _ _ _ _ _ _ _ _ _ _ _ _ _ _ _ _ _ _ _ _ _ _ _ _ _ _ _ _ _ _ _ _ _ _ _

self = <unittest.mock._patch object at 0x7f7c04b381d0>

    def get_original(self):
        target = self.getter()
        name = self.attribute
    
        original = DEFAULT
        local = False
    
        try:
            original = target.__dict__[name]
        except (AttributeError, KeyError):
            original = getattr(target, name, DEFAULT)
        else:
            local = True
    
        if name in _builtins and isinstance(target, ModuleType):
            self.create = True
    
        if not self.create and original is DEFAULT:
>           raise AttributeError(
                "%s does not have the attribute %r" % (target, name)
            )
E           AttributeError: <module 'src.storage.components.database_connection' from '/home/runner/workspace/src/storage/components/database_connection.py'> does not have the attribute 'psycopg2'

/nix/store/7d088dip86hlzri9sk0h78b63yfmx0a0-python3-3.11.13/lib/python3.11/unittest/mock.py:1419: AttributeError
_____________ TestDatabaseConnectionEdgeCases.test_empty_password_handling ______________

self = <tests.test_20_database_connection_coverage.TestDatabaseConnectionEdgeCases object at 0x7f7c04b44210>

    @patch.dict('os.environ', {'PGPASSWORD': ''})
    def test_empty_password_handling(self):
        """Покрытие обработки пустого пароля"""
        db_conn = DatabaseConnection()
    
>       assert db_conn._connection_params["password"] == ""
E       AssertionError: assert 'npg_MPnXu1JWZ5jB' == ''
E         
E         + npg_MPnXu1JWZ5jB

tests/test_20_database_connection_coverage.py:366: AssertionError
__________ TestDatabaseConnectionEdgeCases.test_multiple_get_connection_calls ___________

args = (<tests.test_20_database_connection_coverage.TestDatabaseConnectionEdgeCases object at 0x7f7c04b44590>,)
keywargs = {}

    @wraps(func)
    def patched(*args, **keywargs):
>       with self.decoration_helper(patched,
                                    args,
                                    keywargs) as (newargs, newkeywargs):

/nix/store/7d088dip86hlzri9sk0h78b63yfmx0a0-python3-3.11.13/lib/python3.11/unittest/mock.py:1375: 
_ _ _ _ _ _ _ _ _ _ _ _ _ _ _ _ _ _ _ _ _ _ _ _ _ _ _ _ _ _ _ _ _ _ _ _ _ _ _ _ _ _ _ _ _
/nix/store/7d088dip86hlzri9sk0h78b63yfmx0a0-python3-3.11.13/lib/python3.11/contextlib.py:137: in __enter__
    return next(self.gen)
           ^^^^^^^^^^^^^^
/nix/store/7d088dip86hlzri9sk0h78b63yfmx0a0-python3-3.11.13/lib/python3.11/unittest/mock.py:1357: in decoration_helper
    arg = exit_stack.enter_context(patching)
          ^^^^^^^^^^^^^^^^^^^^^^^^^^^^^^^^^^
/nix/store/7d088dip86hlzri9sk0h78b63yfmx0a0-python3-3.11.13/lib/python3.11/contextlib.py:517: in enter_context
    result = _enter(cm)
             ^^^^^^^^^^
/nix/store/7d088dip86hlzri9sk0h78b63yfmx0a0-python3-3.11.13/lib/python3.11/unittest/mock.py:1446: in __enter__
    original, local = self.get_original()
                      ^^^^^^^^^^^^^^^^^^^
_ _ _ _ _ _ _ _ _ _ _ _ _ _ _ _ _ _ _ _ _ _ _ _ _ _ _ _ _ _ _ _ _ _ _ _ _ _ _ _ _ _ _ _ _

self = <unittest.mock._patch object at 0x7f7c04b38410>

    def get_original(self):
        target = self.getter()
        name = self.attribute
    
        original = DEFAULT
        local = False
    
        try:
            original = target.__dict__[name]
        except (AttributeError, KeyError):
            original = getattr(target, name, DEFAULT)
        else:
            local = True
    
        if name in _builtins and isinstance(target, ModuleType):
            self.create = True
    
        if not self.create and original is DEFAULT:
>           raise AttributeError(
                "%s does not have the attribute %r" % (target, name)
            )
E           AttributeError: <module 'src.storage.components.database_connection' from '/home/runner/workspace/src/storage/components/database_connection.py'> does not have the attribute 'psycopg2'

/nix/store/7d088dip86hlzri9sk0h78b63yfmx0a0-python3-3.11.13/lib/python3.11/unittest/mock.py:1419: AttributeError
_________________ TestDatabaseConnectionIntegration.test_full_lifecycle _________________

args = (<tests.test_20_database_connection_coverage.TestDatabaseConnectionIntegration object at 0x7f7c04b44a10>,)
keywargs = {}

    @wraps(func)
    def patched(*args, **keywargs):
>       with self.decoration_helper(patched,
                                    args,
                                    keywargs) as (newargs, newkeywargs):

/nix/store/7d088dip86hlzri9sk0h78b63yfmx0a0-python3-3.11.13/lib/python3.11/unittest/mock.py:1375: 
_ _ _ _ _ _ _ _ _ _ _ _ _ _ _ _ _ _ _ _ _ _ _ _ _ _ _ _ _ _ _ _ _ _ _ _ _ _ _ _ _ _ _ _ _
/nix/store/7d088dip86hlzri9sk0h78b63yfmx0a0-python3-3.11.13/lib/python3.11/contextlib.py:137: in __enter__
    return next(self.gen)
           ^^^^^^^^^^^^^^
/nix/store/7d088dip86hlzri9sk0h78b63yfmx0a0-python3-3.11.13/lib/python3.11/unittest/mock.py:1357: in decoration_helper
    arg = exit_stack.enter_context(patching)
          ^^^^^^^^^^^^^^^^^^^^^^^^^^^^^^^^^^
/nix/store/7d088dip86hlzri9sk0h78b63yfmx0a0-python3-3.11.13/lib/python3.11/contextlib.py:517: in enter_context
    result = _enter(cm)
             ^^^^^^^^^^
/nix/store/7d088dip86hlzri9sk0h78b63yfmx0a0-python3-3.11.13/lib/python3.11/unittest/mock.py:1446: in __enter__
    original, local = self.get_original()
                      ^^^^^^^^^^^^^^^^^^^
_ _ _ _ _ _ _ _ _ _ _ _ _ _ _ _ _ _ _ _ _ _ _ _ _ _ _ _ _ _ _ _ _ _ _ _ _ _ _ _ _ _ _ _ _

self = <unittest.mock._patch object at 0x7f7c04b38690>

    def get_original(self):
        target = self.getter()
        name = self.attribute
    
        original = DEFAULT
        local = False
    
        try:
            original = target.__dict__[name]
        except (AttributeError, KeyError):
            original = getattr(target, name, DEFAULT)
        else:
            local = True
    
        if name in _builtins and isinstance(target, ModuleType):
            self.create = True
    
        if not self.create and original is DEFAULT:
>           raise AttributeError(
                "%s does not have the attribute %r" % (target, name)
            )
E           AttributeError: <module 'src.storage.components.database_connection' from '/home/runner/workspace/src/storage/components/database_connection.py'> does not have the attribute 'psycopg2'

/nix/store/7d088dip86hlzri9sk0h78b63yfmx0a0-python3-3.11.13/lib/python3.11/unittest/mock.py:1419: AttributeError
__________ TestDatabaseConnectionIntegration.test_connection_recovery_scenario __________

args = (<tests.test_20_database_connection_coverage.TestDatabaseConnectionIntegration object at 0x7f7c04b44f90>,)
keywargs = {}

    @wraps(func)
    def patched(*args, **keywargs):
>       with self.decoration_helper(patched,
                                    args,
                                    keywargs) as (newargs, newkeywargs):

/nix/store/7d088dip86hlzri9sk0h78b63yfmx0a0-python3-3.11.13/lib/python3.11/unittest/mock.py:1375: 
_ _ _ _ _ _ _ _ _ _ _ _ _ _ _ _ _ _ _ _ _ _ _ _ _ _ _ _ _ _ _ _ _ _ _ _ _ _ _ _ _ _ _ _ _
/nix/store/7d088dip86hlzri9sk0h78b63yfmx0a0-python3-3.11.13/lib/python3.11/contextlib.py:137: in __enter__
    return next(self.gen)
           ^^^^^^^^^^^^^^
/nix/store/7d088dip86hlzri9sk0h78b63yfmx0a0-python3-3.11.13/lib/python3.11/unittest/mock.py:1357: in decoration_helper
    arg = exit_stack.enter_context(patching)
          ^^^^^^^^^^^^^^^^^^^^^^^^^^^^^^^^^^
/nix/store/7d088dip86hlzri9sk0h78b63yfmx0a0-python3-3.11.13/lib/python3.11/contextlib.py:517: in enter_context
    result = _enter(cm)
             ^^^^^^^^^^
/nix/store/7d088dip86hlzri9sk0h78b63yfmx0a0-python3-3.11.13/lib/python3.11/unittest/mock.py:1446: in __enter__
    original, local = self.get_original()
                      ^^^^^^^^^^^^^^^^^^^
_ _ _ _ _ _ _ _ _ _ _ _ _ _ _ _ _ _ _ _ _ _ _ _ _ _ _ _ _ _ _ _ _ _ _ _ _ _ _ _ _ _ _ _ _

self = <unittest.mock._patch object at 0x7f7c04b38850>

    def get_original(self):
        target = self.getter()
        name = self.attribute
    
        original = DEFAULT
        local = False
    
        try:
            original = target.__dict__[name]
        except (AttributeError, KeyError):
            original = getattr(target, name, DEFAULT)
        else:
            local = True
    
        if name in _builtins and isinstance(target, ModuleType):
            self.create = True
    
        if not self.create and original is DEFAULT:
>           raise AttributeError(
                "%s does not have the attribute %r" % (target, name)
            )
E           AttributeError: <module 'src.storage.components.database_connection' from '/home/runner/workspace/src/storage/components/database_connection.py'> does not have the attribute 'psycopg2'

/nix/store/7d088dip86hlzri9sk0h78b63yfmx0a0-python3-3.11.13/lib/python3.11/unittest/mock.py:1419: AttributeError
================================ short test summary info ================================
FAILED tests/test_20_database_connection_coverage.py::TestDatabaseConnection::test_init_with_env_params - AssertionError: assert {'command_tim...on.tech', ...} == {'database': ...: '5433', ...}
FAILED tests/test_20_database_connection_coverage.py::TestDatabaseConnection::test_get_default_params_defaults - AssertionError: assert {'command_tim...calhost', ...} == {'database': ...: '5432', ...}
FAILED tests/test_20_database_connection_coverage.py::TestDatabaseConnection::test_get_connection_creates_new_when_none - AttributeError: <module 'src.storage.components.database_connection' from '/home/run...
FAILED tests/test_20_database_connection_coverage.py::TestDatabaseConnection::test_get_connection_reuses_valid_connection - AttributeError: <module 'src.storage.components.database_connection' from '/home/run...
FAILED tests/test_20_database_connection_coverage.py::TestDatabaseConnection::test_get_connection_recreates_invalid_connection - AttributeError: <module 'src.storage.components.database_connection' from '/home/run...
FAILED tests/test_20_database_connection_coverage.py::TestDatabaseConnection::test_is_connection_valid_broken_connection - AttributeError: <module 'src.storage.components.database_connection' from '/home/run...
FAILED tests/test_20_database_connection_coverage.py::TestDatabaseConnection::test_create_new_connection_success - AttributeError: <module 'src.storage.components.database_connection' from '/home/run...
FAILED tests/test_20_database_connection_coverage.py::TestDatabaseConnection::test_create_new_connection_failure - AttributeError: <module 'src.storage.components.database_connection' from '/home/run...
FAILED tests/test_20_database_connection_coverage.py::TestDatabaseConnection::test_create_new_connection_with_cursor_factory - AttributeError: <module 'src.storage.components.database_connection' from '/home/run...
FAILED tests/test_20_database_connection_coverage.py::TestDatabaseConnection::test_context_manager_protocol - AttributeError: <module 'src.storage.components.database_connection' from '/home/run...
FAILED tests/test_20_database_connection_coverage.py::TestDatabaseConnectionEdgeCases::test_psycopg2_not_available - AttributeError: <module 'src.storage.components.database_connection' from '/home/run...
FAILED tests/test_20_database_connection_coverage.py::TestDatabaseConnectionEdgeCases::test_real_dict_cursor_not_available - AttributeError: <module 'src.storage.components.database_connection' from '/home/run...
FAILED tests/test_20_database_connection_coverage.py::TestDatabaseConnectionEdgeCases::test_empty_password_handling - AssertionError: assert 'npg_MPnXu1JWZ5jB' == ''
FAILED tests/test_20_database_connection_coverage.py::TestDatabaseConnectionEdgeCases::test_multiple_get_connection_calls - AttributeError: <module 'src.storage.components.database_connection' from '/home/run...
FAILED tests/test_20_database_connection_coverage.py::TestDatabaseConnectionIntegration::test_full_lifecycle - AttributeError: <module 'src.storage.components.database_connection' from '/home/run...
FAILED tests/test_20_database_connection_coverage.py::TestDatabaseConnectionIntegration::test_connection_recovery_scenario - AttributeError: <module 'src.storage.components.database_connection' from '/home/run...
============================= 16 failed, 9 passed in 2.18s ==============================
~/workspace$ 